<?xml version="1.0"?>
<robot xmlns:xacro="http://www.ros.org/wiki/xacro">
  <!-- <xacro:include filename="$(find aecert_hexapod_description)/urdf/common_properties.xacro" /> -->

  <xacro:macro name="coxa_link" params="name">
    <link name="${name}">
      <inertial>
        <origin xyz="0 0 0" rpy="0 0 0" />
        <mass value="1.3729096e+00" />
        <inertia 
          ixx="4.2111447e-02" ixy="0" ixz="0" 
          iyy="4.2111447e-02" iyz="0" 
          izz="7.5254874e-02" 
        />
      </inertial>

      <collision name="${name}_collision">
        <origin xyz="0.03 0 0" rpy="0 0 0" />
        <geometry>
          <box size="0.085 0.05 0.08" />
        </geometry>
      </collision>

      <visual name="${name}_visual">
        <origin xyz="0 0 0" rpy="0 0 0" />
        <geometry>
          <mesh scale="0.001 0.001 0.001" filename="$(find aecert_hexapod_description)/meshes/coxa.stl" />
        </geometry>
        <material name="light_black" />

      </visual>
    </link>
  </xacro:macro>

  <xacro:macro name="coxa_joint" params="name parent_link child_link x_offs y_offs yaw">
    <joint name="${name}" type="revolute">
      <origin xyz="${x_offs} ${y_offs} 0.025" rpy="0 0 ${yaw}" />
      <parent link="${parent_link}" />
      <child link="${child_link}" />
      <axis xyz="0 0 1" rpy="0 0 0" />
      <limit 
        lower="-1.79769e+308" 
        upper="1.79769e+308" 
        effort="1000" 
        velocity="1000"
      />
    </joint>

    <ros2_control name="GazeboSimSystem" type="system">
      <hardware>
        <plugin>gz_ros2_control/GazeboSimSystem</plugin>
      </hardware>
      <joint name="${name}">
        <command_interface name="position">
          <param name="min">{-2*PI}</param>
          <param name="max">{2*PI}</param>
        </command_interface>
        <command_interface name="velocity">
          <param name="min">-3.15</param>
          <param name="max">3.15</param>
        </command_interface>
        <state_interface name="position">
          <param name="initial_value">0.0</param>
        </state_interface>
        <state_interface name="velocity"/>
      </joint>
    </ros2_control>

  </xacro:macro>

</robot>